<?xml version="1.0"?>
<robot name="elderly_bot">
  
  <!-- ========== BASE FOOTPRINT (ground level) ========== -->
  <link name="base_footprint">
    <visual>
      <geometry>
        <box size="0.01 0.01 0.01"/>
      </geometry>
      <material name="transparent">
        <color rgba="0 0 0 0"/>
      </material>
    </visual>
  </link>

  <!-- ========== BASE LINK (chassis) ========== -->
  <joint name="base_footprint_to_base_link" type="fixed">
    <parent link="base_footprint"/>
    <child link="base_link"/>
    <origin xyz="0 0 0.075" rpy="0 0 0"/>
  </joint>

  <link name="base_link">
    <visual>
      <geometry>
        <box size="0.35 0.25 0.14"/>
      </geometry>
      <origin xyz="0 0 0.07" rpy="0 0 0"/>
      <material name="black">
        <color rgba="0.1 0.1 0.1 1"/>
      </material>
    </visual>
    <collision>
      <geometry>
        <box size="0.35 0.25 0.14"/>
      </geometry>
      <origin xyz="0 0 0.07" rpy="0 0 0"/>
    </collision>
    <inertial>
      <mass value="3.0"/>
      <origin xyz="0 0 0.07" rpy="0 0 0"/>
      <inertia ixx="0.05" ixy="0.0" ixz="0.0" iyy="0.05" iyz="0.0" izz="0.05"/>
    </inertial>
  </link>

  <!-- ========== WHEELS ========== -->
  <!-- Front Left Wheel -->
  <joint name="front_left_wheel_joint" type="continuous">
    <parent link="base_link"/>
    <child link="front_left_wheel"/>
    <origin xyz="0.10 0.13 -0.05" rpy="0 0 0"/>
    <axis xyz="0 1 0"/>
  </joint>

  <link name="front_left_wheel">
    <visual>
      <geometry>
        <cylinder radius="0.0388" length="0.025"/>
      </geometry>
      <origin xyz="0 0 0" rpy="1.57079632679 0 0"/>
      <material name="wheel_color">
        <color rgba="0.2 0.2 0.2 1"/>
      </material>
    </visual>
    <collision>
      <geometry>
        <cylinder radius="0.0388" length="0.025"/>
      </geometry>
      <origin xyz="0 0 0" rpy="1.57079632679 0 0"/>
    </collision>
    <inertial>
      <mass value="0.2"/>
      <inertia ixx="0.001" ixy="0.0" ixz="0.0" iyy="0.001" iyz="0.0" izz="0.001"/>
    </inertial>
  </link>

  <!-- Front Right Wheel -->
  <joint name="front_right_wheel_joint" type="continuous">
    <parent link="base_link"/>
    <child link="front_right_wheel"/>
    <origin xyz="0.10 -0.13 -0.05" rpy="0 0 0"/>
    <axis xyz="0 1 0"/>
  </joint>

  <link name="front_right_wheel">
    <visual>
      <geometry>
        <cylinder radius="0.0388" length="0.025"/>
      </geometry>
      <origin xyz="0 0 0" rpy="1.57079632679 0 0"/>
      <material name="wheel_color">
        <color rgba="0.2 0.2 0.2 1"/>
      </material>
    </visual>
    <collision>
      <geometry>
        <cylinder radius="0.0388" length="0.025"/>
      </geometry>
      <origin xyz="0 0 0" rpy="1.57079632679 0 0"/>
    </collision>
    <inertial>
      <mass value="0.2"/>
      <inertia ixx="0.001" ixy="0.0" ixz="0.0" iyy="0.001" iyz="0.0" izz="0.001"/>
    </inertial>
  </link>

  <!-- Rear Left Wheel -->
  <joint name="rear_left_wheel_joint" type="continuous">
    <parent link="base_link"/>
    <child link="rear_left_wheel"/>
    <origin xyz="-0.10 0.13 -0.05" rpy="0 0 0"/>
    <axis xyz="0 1 0"/>
  </joint>

  <link name="rear_left_wheel">
    <visual>
      <geometry>
        <cylinder radius="0.0388" length="0.025"/>
      </geometry>
      <origin xyz="0 0 0" rpy="1.57079632679 0 0"/>
      <material name="wheel_color">
        <color rgba="0.2 0.2 0.2 1"/>
      </material>
    </visual>
    <collision>
      <geometry>
        <cylinder radius="0.0388" length="0.025"/>
      </geometry>
      <origin xyz="0 0 0" rpy="1.57079632679 0 0"/>
    </collision>
    <inertial>
      <mass value="0.2"/>
      <inertia ixx="0.001" ixy="0.0" ixz="0.0" iyy="0.001" iyz="0.0" izz="0.001"/>
    </inertial>
  </link>

  <!-- Rear Right Wheel -->
  <joint name="rear_right_wheel_joint" type="continuous">
    <parent link="base_link"/>
    <child link="rear_right_wheel"/>
    <origin xyz="-0.10 -0.13 -0.05" rpy="0 0 0"/>
    <axis xyz="0 1 0"/>
  </joint>

  <link name="rear_right_wheel">
    <visual>
      <geometry>
        <cylinder radius="0.0388" length="0.025"/>
      </geometry>
      <origin xyz="0 0 0" rpy="1.57079632679 0 0"/>
      <material name="wheel_color">
        <color rgba="0.2 0.2 0.2 1"/>
      </material>
    </visual>
    <collision>
      <geometry>
        <cylinder radius="0.0388" length="0.025"/>
      </geometry>
      <origin xyz="0 0 0" rpy="1.57079632679 0 0"/>
    </collision>
    <inertial>
      <mass value="0.2"/>
      <inertia ixx="0.001" ixy="0.0" ixz="0.0" iyy="0.001" iyz="0.0" izz="0.001"/>
    </inertial>
  </link>

  <!-- ========== LIDAR (on top of chassis) ========== -->
  <joint name="base_link_to_laser" type="fixed">
    <parent link="base_link"/>
    <child link="laser"/>
    <!-- Lidar on top of 21cm box, facing backward (180° yaw) -->
    <origin xyz="0 0 0.21" rpy="0 0 3.14159265359"/>
  </joint>

  <link name="laser">
    <visual>
      <geometry>
        <cylinder radius="0.035" length="0.04"/>
      </geometry>
      <material name="red">
        <color rgba="0.8 0.1 0.1 1"/>
      </material>
    </visual>
    <collision>
      <geometry>
        <cylinder radius="0.035" length="0.04"/>
      </geometry>
    </collision>
    <inertial>
      <mass value="0.15"/>
      <inertia ixx="0.0001" ixy="0.0" ixz="0.0" iyy="0.0001" iyz="0.0" izz="0.0001"/>
    </inertial>
  </link>

  <!-- ========== IMU ========== -->
  <joint name="base_link_to_imu_link" type="fixed">
    <parent link="base_link"/>
    <child link="imu_link"/>
    <origin xyz="0 0 0" rpy="3.14159265359 3.14159265359 0"/>
  </joint>

  <link name="imu_link">
    <visual>
      <geometry>
        <box size="0.02 0.02 0.01"/>
      </geometry>
      <material name="blue">
        <color rgba="0.1 0.1 0.8 1"/>
      </material>
    </visual>
    <inertial>
      <mass value="0.01"/>
      <inertia ixx="0.00001" ixy="0.0" ixz="0.0" iyy="0.00001" iyz="0.0" izz="0.00001"/>
    </inertial>
  </link>

</robot>
